Workbook

Sheet Master list
A1: UBCO Heat vs Regina · first half · master list from handwritten notes
A2: Yellow rows need a look. Fix a row by changing the notes and telling me, or by editing the play in the app after import. Stat columns add up on the Totals sheet.
A3: # | B3: Page | C3: Period | D3: Video time | E3: Player | F3: As written in the notes | G3: Booked as | H3: Check | I3: PTS | J3: FGM | K3: FGA | L3: 3PM | M3: 3PA | N3: FTM | O3: FTA | P3: OREB | Q3: DREB | R3: AST | S3: STL | T3: BLK | U3: TOV | V3: PF | W3: HVP
A4: 1 | B4: 1 | C4: Q1 | D4: 0:06 | E4: Mathias Schertzer | F4: [top line cut off by scan] … MADE & PAINT TOUCH BEFORE | G4: 2PT make | I4: 2 | J4: 1 | K4: 1 | L4: 0 | M4: 0 | N4: 0 | O4: 0 | P4: 0 | Q4: 0 | R4: 0 | S4: 0 | T4: 0 | U4: 0 | V4: 0 | W4: 0
A5: 2 | B5: 1 | C5: Q1 | D5: 0:06 | E5: Mathias Schertzer | F5: PAINT TOUCH BEFORE | G5: Paint touch | I5: 0 | J5: 0 | K5: 0 | L5: 0 | M5: 0 | N5: 0 | O5: 0 | P5: 0 | Q5: 0 | R5: 0 | S5: 0 | T5: 0 | U5: 0 | V5: 0 | W5: 2
A6: 3 | B6: 1 | C6: Q1 | D6: 0:06 | E6: Enrique Garcia | F6: ASSIST | G6: Assist | I6: 0 | J6: 0 | K6: 0 | L6: 0 | M6: 0 | N6: 0 | O6: 0 | P6: 0 | Q6: 0 | R6: 1 | S6: 0 | T6: 0 | U6: 0 | V6: 0 | W6: 0
A7: 4 | B7: 1 | C7: Q1 | D7: 0:06 | E7: Enrique Garcia | F7: RIGHT READ | G7: Right read | I7: 0 | J7: 0 | K7: 0 | L7: 0 | M7: 0 | N7: 0 | O7: 0 | P7: 0 | Q7: 0 | R7: 0 | S7: 0 | T7: 0 | U7: 0 | V7: 0 | W7: 1
A8: 5 | B8: 1 | C8: Q1 | D8: 0:15 | E8: Isaak Moore | F8: YOU | G8: YOU | H8: Written as :015 | I8: 0 | J8: 0 | K8: 0 | L8: 0 | M8: 0 | N8: 0 | O8: 0 | P8: 0 | Q8: 0 | R8: 0 | S8: 0 | T8: 0 | U8: 0 | V8: 0 | W8: 1
A9: 6 | B9: 1 | C9: Q1 | D9: 0:45 | E9: Lamine Conde | F9: MISSED 2 & PAINT TOUCH BEFORE | G9: 2PT miss | I9: 0 | J9: 0 | K9: 1 | L9: 0 | M9: 0 | N9: 0 | O9: 0 | P9: 0 | Q9: 0 | R9: 0 | S9: 0 | T9: 0 | U9: 0 | V9: 0 | W9: 0
A10: 7 | B10: 1 | C10: Q1 | D10: 0:45 | E10: Lamine Conde | F10: (paint touch before) | G10: Paint touch | I10: 0 | J10: 0 | K10: 0 | L10: 0 | M10: 0 | N10: 0 | O10: 0 | P10: 0 | Q10: 0 | R10: 0 | S10: 0 | T10: 0 | U10: 0 | V10: 0 | W10: 2
A11: 8 | B11: 1 | C11: Q1 | D11: 0:50 | E11: Tylen Lewis | F11: TIP | G11: Tip | I11: 0 | J11: 0 | K11: 0 | L11: 0 | M11: 0 | N11: 0 | O11: 0 | P11: 0 | Q11: 0 | R11: 0 | S11: 0 | T11: 0 | U11: 0 | V11: 0 | W11: 1
A12: 9 | B12: 1 | C12: Q1 | D12: 1:17 | E12: Isaak Moore | F12: MISSED THREE | G12: 3PT miss | I12: 0 | J12: 0 | K12: 1 | L12: 0 | M12: 1 | N12: 0 | O12: 0 | P12: 0 | Q12: 0 | R12: 0 | S12: 0 | T12: 0 | U12: 0 | V12: 0 | W12: 0
A13: 10 | B13: 1 | C13: Q1 | D13: 1:25 | E13: Enrique Garcia | F13: WALL UP | G13: WallUp | I13: 0 | J13: 0 | K13: 0 | L13: 0 | M13: 0 | N13: 0 | O13: 0 | P13: 0 | Q13: 0 | R13: 0 | S13: 0 | T13: 0 | U13: 0 | V13: 0 | W13: 1
A14: 11 | B14: 1 | C14: Q1 | D14: 2:36 | E14: Enrique Garcia | F14: RIGHT READ | G14: Right read | I14: 0 | J14: 0 | K14: 0 | L14: 0 | M14: 0 | N14: 0 | O14: 0 | P14: 0 | Q14: 0 | R14: 0 | S14: 0 | T14: 0 | U14: 0 | V14: 0 | W14: 1
A15: 12 | B15: 1 | C15: Q1 | D15: 2:41 | E15: Lamine Conde | F15: PAINT TOUCH | G15: Paint touch | I15: 0 | J15: 0 | K15: 0 | L15: 0 | M15: 0 | N15: 0 | O15: 0 | P15: 0 | Q15: 0 | R15: 0 | S15: 0 | T15: 0 | U15: 0 | V15: 0 | W15: 2
A16: 13 | B16: 1 | C16: Q1 | D16: 2:45 | E16: Lamine Conde | F16: UPCYCLE | G16: Upcycle | I16: 0 | J16: 0 | K16: 0 | L16: 0 | M16: 0 | N16: 0 | O16: 0 | P16: 0 | Q16: 0 | R16: 0 | S16: 0 | T16: 0 | U16: 0 | V16: 0 | W16: 1
A17: 14 | B17: 1 | C17: Q1 | D17: 2:48 | E17: Isaak Moore | F17: UPCYCLE | G17: Upcycle | I17: 0 | J17: 0 | K17: 0 | L17: 0 | M17: 0 | N17: 0 | O17: 0 | P17: 0 | Q17: 0 | R17: 0 | S17: 0 | T17: 0 | U17: 0 | V17: 0 | W17: 1
A18: 15 | B18: 1 | C18: Q1 | D18: 2:51 | E18: Lamine Conde | F18: MISSED 3 + RIGHT READ | G18: 3PT miss | I18: 0 | J18: 0 | K18: 1 | L18: 0 | M18: 1 | N18: 0 | O18: 0 | P18: 0 | Q18: 0 | R18: 0 | S18: 0 | T18: 0 | U18: 0 | V18: 0 | W18: 0
A19: 16 | B19: 1 | C19: Q1 | D19: 2:51 | E19: Lamine Conde | F19: (+ right read) | G19: Right read | I19: 0 | J19: 0 | K19: 0 | L19: 0 | M19: 0 | N19: 0 | O19: 0 | P19: 0 | Q19: 0 | R19: 0 | S19: 0 | T19: 0 | U19: 0 | V19: 0 | W19: 1
A20: 17 | B20: 1 | C20: Q1 | D20: 2:53 | E20: Enrique Garcia | F20: PURSUIT | G20: Pursuit | I20: 0 | J20: 0 | K20: 0 | L20: 0 | M20: 0 | N20: 0 | O20: 0 | P20: 0 | Q20: 0 | R20: 0 | S20: 0 | T20: 0 | U20: 0 | V20: 0 | W20: 2
... A26: 23 | B26: 1 | C26: Q1 | D26: 4:20 | E26: Lamine Conde | F26: PAINT TOUCH IN 6 | G26: Paint touch in 6 | I26: 0 | J26: 0 | K26: 0 | L26: 0 | M26: 0 | N26: 0 | O26: 0 | P26: 0 | Q26: 0 | R26: 0 | S26: 0 | T26: 0 | U26: 0 | V26: 0 | W26: 3
A27: 24 | B27: 1 | C27: Q1 | D27: 4:24 | E27: Lamine Conde | F27: TURNOVER | G27: Turnover (type not given) | H27: Turnover type not written | I27: 0 | J27: 0 | K27: 0 | L27: 0 | M27: 0 | N27: 0 | O27: 0 | P27: 0 | Q27: 0 | R27: 0 | S27: 0 | T27: 0 | U27: 1 | V27: 0 | W27: 0
A28: 25 | B28: 2 | C28: Q1 | D28: 4:57 | E28: Michael Adarkwah Nti | F28: PAINT TOUCH | G28: Paint touch | I28: 0 | J28: 0 | K28: 0 | L28: 0 | M28: 0 | N28: 0 | O28: 0 | P28: 0 | Q28: 0 | R28: 0 | S28: 0 | T28: 0 | U28: 0 | V28: 0 | W28: 2
A29: 26 | B29: 2 | C29: Q1 | D29: 4:58 | E29: Michael Adarkwah Nti | F29: RIGHT READ | G29: Right read | I29: 0 | J29: 0 | K29: 0 | L29: 0 | M29: 0 | N29: 0 | O29: 0 | P29: 0 | Q29: 0 | R29: 0 | S29: 0 | T29: 0 | U29: 0 | V29: 0 | W29: 1
A30: 27 | B30: 2 | C30: Q1 | D30: 4:59 | E30: Michael Adarkwah Nti | F30: ASSIST | G30: Assist | I30: 0 | J30: 0 | K30: 0 | L30: 0 | M30: 0 | N30: 0 | O30: 0 | P30: 0 | Q30: 0 | R30: 1 | S30: 0 | T30: 0 | U30: 0 | V30: 0 | W30: 0
A31: 28 | B31: 2 | C31: Q1 | D31: 5:00 | E31: Tylen Lewis | F31: MADE 2 | G31: 2PT make | I31: 2 | J31: 1 | K31: 1 | L31: 0 | M31: 0 | N31: 0 | O31: 0 | P31: 0 | Q31: 0 | R31: 0 | S31: 0 | T31: 0 | U31: 0 | V31: 0 | W31: 0
A32: 29 | B32: 2 | C32: Q1 | D32: 5:11 | E32: Michael Adarkwah Nti | F32: YOU | G32: YOU | I32: 0 | J32: 0 | K32: 0 | L32: 0 | M32: 0 | N32: 0 | O32: 0 | P32: 0 | Q32: 0 | R32: 0 | S32: 0 | T32: 0 | U32: 0 | V32: 0 | W32: 1
A33: 30 | B33: 2 | C33: Q1 | D33: 5:15 | E33: Mathias Schertzer | F33: YOU | G33: YOU | I33: 0 | J33: 0 | K33: 0 | L33: 0 | M33: 0 | N33: 0 | O33: 0 | P33: 0 | Q33: 0 | R33: 0 | S33: 0 | T33: 0 | U33: 0 | V33: 0 | W33: 1
A34: 31 | B34: 2 | C34: Q1 | D34: 5:20 | E34: Mathias Schertzer | F34: YOU | G34: YOU | I34: 0 | J34: 0 | K34: 0 | L34: 0 | M34: 0 | N34: 0 | O34: 0 | P34: 0 | Q34: 0 | R34: 0 | S34: 0 | T34: 0 | U34: 0 | V34: 0 | W34: 1
A35: 32 | B35: 2 | C35: Q1 | D35: 5:40 | E35: Isaak Moore | F35: RIGHT READ | G35: Right read | I35: 0 | J35: 0 | K35: 0 | L35: 0 | M35: 0 | N35: 0 | O35: 0 | P35: 0 | Q35: 0 | R35: 0 | S35: 0 | T35: 0 | U35: 0 | V35: 0 | W35: 1
A36: 33 | B36: 2 | C36: Q1 | D36: 5:44 | E36: Lamine Conde | F36: RIGHT READ | G36: Right read | I36: 0 | J36: 0 | K36: 0 | L36: 0 | M36: 0 | N36: 0 | O36: 0 | P36: 0 | Q36: 0 | R36: 0 | S36: 0 | T36: 0 | U36: 0 | V36: 0 | W36: 1
A37: 34 | B37: 2 | C37: Q1 | D37: 5:46 | E37: Tylen Lewis | F37: MISSED THREE | G37: 3PT miss | I37: 0 | J37: 0 | K37: 1 | L37: 0 | M37: 1 | N37: 0 | O37: 0 | P37: 0 | Q37: 0 | R37: 0 | S37: 0 | T37: 0 | U37: 0 | V37: 0 | W37: 0
A38: 35 | B38: 2 | C38: Q1 | D38: 7:42 | E38: Mathias Schertzer | F38: UPCYCLE or RIGHT READ | G38: Upcycle | I38: 0 | J38: 0 | K38: 0 | L38: 0 | M38: 0 | N38: 0 | O38: 0 | P38: 0 | Q38: 0 | R38: 0 | S38: 0 | T38: 0 | U38: 0 | V38: 0 | W38: 1
A39: 36 | B39: 2 | C39: Q1 | D39: 7:43 | E39: Michael Adarkwah Nti | F39: PAINT TOUCH | G39: Paint touch | I39: 0 | J39: 0 | K39: 0 | L39: 0 | M39: 0 | N39: 0 | O39: 0 | P39: 0 | Q39: 0 | R39: 0 | S39: 0 | T39: 0 | U39: 0 | V39: 0 | W39: 2
... A42: 39 | B42: 2 | C42: Q1 | D42: 8:14 | E42: Lamine Conde | F42: MISSED TWO | G42: 2PT miss | I42: 0 | J42: 0 | K42: 1 | L42: 0 | M42: 0 | N42: 0 | O42: 0 | P42: 0 | Q42: 0 | R42: 0 | S42: 0 | T42: 0 | U42: 0 | V42: 0 | W42: 0
A43: 40 | B43: 2 | C43: Q1 | D43: 8:14 | E43: Anthony Brady | F43: TIP | G43: Tip | H43: A name before Anthony is crossed out | I43: 0 | J43: 0 | K43: 0 | L43: 0 | M43: 0 | N43: 0 | O43: 0 | P43: 0 | Q43: 0 | R43: 0 | S43: 0 | T43: 0 | U43: 0 | V43: 0 | W43: 1
A44: 41 | B44: 2 | C44: Q1 | D44: 8:14 | E44: Mathias Schertzer | F44: O-BOARD | G44: Off. rebound | I44: 0 | J44: 0 | K44: 0 | L44: 0 | M44: 0 | N44: 0 | O44: 0 | P44: 1 | Q44: 0 | R44: 0 | S44: 0 | T44: 0 | U44: 0 | V44: 0 | W44: 3
A45: 42 | B45: 2 | C45: Q1 | D45: 8:14 | E45: Mathias Schertzer | F45: PAINT TOUCH | G45: Paint touch | I45: 0 | J45: 0 | K45: 0 | L45: 0 | M45: 0 | N45: 0 | O45: 0 | P45: 0 | Q45: 0 | R45: 0 | S45: 0 | T45: 0 | U45: 0 | V45: 0 | W45: 2
A46: 43 | B46: 2 | C46: Q1 | D46: 8:17 | E46: Mathias Schertzer | F46: MISSED TWO | G46: 2PT miss | I46: 0 | J46: 0 | K46: 1 | L46: 0 | M46: 0 | N46: 0 | O46: 0 | P46: 0 | Q46: 0 | R46: 0 | S46: 0 | T46: 0 | U46: 0 | V46: 0 | W46: 0
A47: 44 | B47: 2 | C47: Q1 | D47: 8:19 | E47: Anthony Brady | F47: O-BOARD | G47: Off. rebound | I47: 0 | J47: 0 | K47: 0 | L47: 0 | M47: 0 | N47: 0 | O47: 0 | P47: 1 | Q47: 0 | R47: 0 | S47: 0 | T47: 0 | U47: 0 | V47: 0 | W47: 3
...

Sheet Totals
A1: Player totals from the master list (formulas)
A2: EFF = PTS + REB + AST + STL + BLK − missed FG − missed FT − TOV. Combined = EFF + HVP × 1/3 (steals, blocks and offensive rebounds count as HVP automatically).
A3: Player | B3: PTS | C3: FGM | D3: FGA | E3: 3PM | F3: 3PA | G3: FTM | H3: FTA | I3: OREB | J3: DREB | K3: AST | L3: STL | M3: BLK | N3: TOV | O3: PF | P3: REB | Q3: EFF | R3: Raw HVP | S3: Adj HVP | T3: Combined
A4: Michael Adarkwah Nti | B4: =SUMIF('Master list'!$E$4:$E$185,$A4,'Master list'!I$4:I$185) -> 6 | C4: =SUMIF('Master list'!$E$4:$E$185,$A4,'Master list'!J$4:J$185) -> 2 | D4: =SUMIF('Master list'!$E$4:$E$185,$A4,'Master list'!K$4:K$185) -> 3 | E4: =SUMIF('Master list'!$E$4:$E$185,$A4,'Master list'!L$4:L$185) -> 0 | F4: =SUMIF('Master list'!$E$4:$E$185,$A4,'Master list'!M$4:M$185) -> 0 | G4: =SUMIF('Master list'!$E$4:$E$185,$A4,'Master list'!N$4:N$185) -> 2 | H4: =SUMIF('Master list'!$E$4:$E$185,$A4,'Master list'!O$4:O$185) -> 3 | I4: =SUMIF('Master list'!$E$4:$E$185,$A4,'Master list'!P$4:P$185) -> 0 | ... O4: =SUMIF('Master list'!$E$4:$E$185,$A4,'Master list'!V$4:V$185) -> 1 | P4: =I4+J4 -> 4 | Q4: =B4+P4+K4+L4+M4-(D4-C4)-(H4-G4)-N4 -> 16 | R4: =SUMIF('Master list'!$E$4:$E$185,$A4,'Master list'!W$4:W$185) -> 37 | S4: =R4/3 -> 12.333333 | T4: =Q4+S4 -> 28.333333
A5: Lamine Conde | B5: =SUMIF('Master list'!$E$4:$E$185,$A5,'Master list'!I$4:I$185) -> 6 | C5: =SUMIF('Master list'!$E$4:$E$185,$A5,'Master list'!J$4:J$185) -> 1 | D5: =SUMIF('Master list'!$E$4:$E$185,$A5,'Master list'!K$4:K$185) -> 8 | E5: =SUMIF('Master list'!$E$4:$E$185,$A5,'Master list'!L$4:L$185) -> 0 | F5: =SUMIF('Master list'!$E$4:$E$185,$A5,'Master list'!M$4:M$185) -> 3 | G5: =SUMIF('Master list'!$E$4:$E$185,$A5,'Master list'!N$4:N$185) -> 4 | H5: =SUMIF('Master list'!$E$4:$E$185,$A5,'Master list'!O$4:O$185) -> 5 | I5: =SUMIF('Master list'!$E$4:$E$185,$A5,'Master list'!P$4:P$185) -> 1 | ... O5: =SUMIF('Master list'!$E$4:$E$185,$A5,'Master list'!V$4:V$185) -> 1 | P5: =I5+J5 -> 3 | Q5: =B5+P5+K5+L5+M5-(D5-C5)-(H5-G5)-N5 -> -1 | R5: =SUMIF('Master list'!$E$4:$E$185,$A5,'Master list'!W$4:W$185) -> 20 | S5: =R5/3 -> 6.6666667 | T5: =Q5+S5 -> 5.6666667
A6: Anthony Brady | B6: =SUMIF('Master list'!$E$4:$E$185,$A6,'Master list'!I$4:I$185) -> 2 | C6: =SUMIF('Master list'!$E$4:$E$185,$A6,'Master list'!J$4:J$185) -> 0 | D6: =SUMIF('Master list'!$E$4:$E$185,$A6,'Master list'!K$4:K$185) -> 1 | E6: =SUMIF('Master list'!$E$4:$E$185,$A6,'Master list'!L$4:L$185) -> 0 | F6: =SUMIF('Master list'!$E$4:$E$185,$A6,'Master list'!M$4:M$185) -> 1 | G6: =SUMIF('Master list'!$E$4:$E$185,$A6,'Master list'!N$4:N$185) -> 2 | H6: =SUMIF('Master list'!$E$4:$E$185,$A6,'Master list'!O$4:O$185) -> 2 | I6: =SUMIF('Master list'!$E$4:$E$185,$A6,'Master list'!P$4:P$185) -> 1 | ... O6: =SUMIF('Master list'!$E$4:$E$185,$A6,'Master list'!V$4:V$185) -> 0 | P6: =I6+J6 -> 3 | Q6: =B6+P6+K6+L6+M6-(D6-C6)-(H6-G6)-N6 -> 6 | R6: =SUMIF('Master list'!$E$4:$E$185,$A6,'Master list'!W$4:W$185) -> 15 | S6: =R6/3 -> 5 | T6: =Q6+S6 -> 11
A7: Isaak Moore | B7: =SUMIF('Master list'!$E$4:$E$185,$A7,'Master list'!I$4:I$185) -> 7 | C7: =SUMIF('Master list'!$E$4:$E$185,$A7,'Master list'!J$4:J$185) -> 3 | D7: =SUMIF('Master list'!$E$4:$E$185,$A7,'Master list'!K$4:K$185) -> 6 | E7: =SUMIF('Master list'!$E$4:$E$185,$A7,'Master list'!L$4:L$185) -> 1 | F7: =SUMIF('Master list'!$E$4:$E$185,$A7,'Master list'!M$4:M$185) -> 3 | G7: =SUMIF('Master list'!$E$4:$E$185,$A7,'Master list'!N$4:N$185) -> 0 | H7: =SUMIF('Master list'!$E$4:$E$185,$A7,'Master list'!O$4:O$185) -> 0 | I7: =SUMIF('Master list'!$E$4:$E$185,$A7,'Master list'!P$4:P$185) -> 0 | ... O7: =SUMIF('Master list'!$E$4:$E$185,$A7,'Master list'!V$4:V$185) -> 0 | P7: =I7+J7 -> 0 | Q7: =B7+P7+K7+L7+M7-(D7-C7)-(H7-G7)-N7 -> 5 | R7: =SUMIF('Master list'!$E$4:$E$185,$A7,'Master list'!W$4:W$185) -> 12 | S7: =R7/3 -> 4 | T7: =Q7+S7 -> 9
A8: Mathias Schertzer | B8: =SUMIF('Master list'!$E$4:$E$185,$A8,'Master list'!I$4:I$185) -> 4 | C8: =SUMIF('Master list'!$E$4:$E$185,$A8,'Master list'!J$4:J$185) -> 2 | D8: =SUMIF('Master list'!$E$4:$E$185,$A8,'Master list'!K$4:K$185) -> 3 | E8: =SUMIF('Master list'!$E$4:$E$185,$A8,'Master list'!L$4:L$185) -> 0 | F8: =SUMIF('Master list'!$E$4:$E$185,$A8,'Master list'!M$4:M$185) -> 0 | G8: =SUMIF('Master list'!$E$4:$E$185,$A8,'Master list'!N$4:N$185) -> 0 | H8: =SUMIF('Master list'!$E$4:$E$185,$A8,'Master list'!O$4:O$185) -> 0 | I8: =SUMIF('Master list'!$E$4:$E$185,$A8,'Master list'!P$4:P$185) -> 1 | ... O8: =SUMIF('Master list'!$E$4:$E$185,$A8,'Master list'!V$4:V$185) -> 0 | P8: =I8+J8 -> 2 | Q8: =B8+P8+K8+L8+M8-(D8-C8)-(H8-G8)-N8 -> 4 | R8: =SUMIF('Master list'!$E$4:$E$185,$A8,'Master list'!W$4:W$185) -> 16 | S8: =R8/3 -> 5.3333333 | T8: =Q8+S8 -> 9.3333333
A9: Enrique Garcia | B9: =SUMIF('Master list'!$E$4:$E$185,$A9,'Master list'!I$4:I$185) -> 0 | C9: =SUMIF('Master list'!$E$4:$E$185,$A9,'Master list'!J$4:J$185) -> 0 | D9: =SUMIF('Master list'!$E$4:$E$185,$A9,'Master list'!K$4:K$185) -> 0 | E9: =SUMIF('Master list'!$E$4:$E$185,$A9,'Master list'!L$4:L$185) -> 0 | F9: =SUMIF('Master list'!$E$4:$E$185,$A9,'Master list'!M$4:M$185) -> 0 | G9: =SUMIF('Master list'!$E$4:$E$185,$A9,'Master list'!N$4:N$185) -> 0 | H9: =SUMIF('Master list'!$E$4:$E$185,$A9,'Master list'!O$4:O$185) -> 0 | I9: =SUMIF('Master list'!$E$4:$E$185,$A9,'Master list'!P$4:P$185) -> 0 | ... O9: =SUMIF('Master list'!$E$4:$E$185,$A9,'Master list'!V$4:V$185) -> 0 | P9: =I9+J9 -> 0 | Q9: =B9+P9+K9+L9+M9-(D9-C9)-(H9-G9)-N9 -> 2 | R9: =SUMIF('Master list'!$E$4:$E$185,$A9,'Master list'!W$4:W$185) -> 12 | S9: =R9/3 -> 4 | T9: =Q9+S9 -> 6
A10: Tylen Lewis | B10: =SUMIF('Master list'!$E$4:$E$185,$A10,'Master list'!I$4:I$185) -> 2 | C10: =SUMIF('Master list'!$E$4:$E$185,$A10,'Master list'!J$4:J$185) -> 1 | D10: =SUMIF('Master list'!$E$4:$E$185,$A10,'Master list'!K$4:K$185) -> 4 | E10: =SUMIF('Master list'!$E$4:$E$185,$A10,'Master list'!L$4:L$185) -> 0 | F10: =SUMIF('Master list'!$E$4:$E$185,$A10,'Master list'!M$4:M$185) -> 1 | G10: =SUMIF('Master list'!$E$4:$E$185,$A10,'Master list'!N$4:N$185) -> 0 | H10: =SUMIF('Master list'!$E$4:$E$185,$A10,'Master list'!O$4:O$185) -> 0 | I10: =SUMIF('Master list'!$E$4:$E$185,$A10,'Master list'!P$4:P$185) -> 1 | ... O10: =SUMIF('Master list'!$E$4:$E$185,$A10,'Master list'!V$4:V$185) -> 0 | P10: =I10+J10 -> 1 | Q10: =B10+P10+K10+L10+M10-(D10-C10)-(H10-G10)-N10 -> -1 | R10: =SUMIF('Master list'!$E$4:$E$185,$A10,'Master list'!W$4:W$185) -> 10 | S10: =R10/3 -> 3.3333333 | T10: =Q10+S10 -> 2.3333333
A11: Will Zylyk | B11: =SUMIF('Master list'!$E$4:$E$185,$A11,'Master list'!I$4:I$185) -> 5 | C11: =SUMIF('Master list'!$E$4:$E$185,$A11,'Master list'!J$4:J$185) -> 2 | D11: =SUMIF('Master list'!$E$4:$E$185,$A11,'Master list'!K$4:K$185) -> 3 | E11: =SUMIF('Master list'!$E$4:$E$185,$A11,'Master list'!L$4:L$185) -> 1 | F11: =SUMIF('Master list'!$E$4:$E$185,$A11,'Master list'!M$4:M$185) -> 1 | G11: =SUMIF('Master list'!$E$4:$E$185,$A11,'Master list'!N$4:N$185) -> 0 | H11: =SUMIF('Master list'!$E$4:$E$185,$A11,'Master list'!O$4:O$185) -> 0 | I11: =SUMIF('Master list'!$E$4:$E$185,$A11,'Master list'!P$4:P$185) -> 1 | ... O11: =SUMIF('Master list'!$E$4:$E$185,$A11,'Master list'!V$4:V$185) -> 2 | P11: =I11+J11 -> 1 | Q11: =B11+P11+K11+L11+M11-(D11-C11)-(H11-G11)-N11 -> 6 | R11: =SUMIF('Master list'!$E$4:$E$185,$A11,'Master list'!W$4:W$185) -> 12 | S11: =R11/3 -> 4 | T11: =Q11+S11 -> 10
A12: Tarun Saroya | B12: =SUMIF('Master list'!$E$4:$E$185,$A12,'Master list'!I$4:I$185) -> 1 | C12: =SUMIF('Master list'!$E$4:$E$185,$A12,'Master list'!J$4:J$185) -> 0 | D12: =SUMIF('Master list'!$E$4:$E$185,$A12,'Master list'!K$4:K$185) -> 2 | E12: =SUMIF('Master list'!$E$4:$E$185,$A12,'Master list'!L$4:L$185) -> 0 | F12: =SUMIF('Master list'!$E$4:$E$185,$A12,'Master list'!M$4:M$185) -> 1 | G12: =SUMIF('Master list'!$E$4:$E$185,$A12,'Master list'!N$4:N$185) -> 1 | H12: =SUMIF('Master list'!$E$4:$E$185,$A12,'Master list'!O$4:O$185) -> 2 | I12: =SUMIF('Master list'!$E$4:$E$185,$A12,'Master list'!P$4:P$185) -> 1 | ... O12: =SUMIF('Master list'!$E$4:$E$185,$A12,'Master list'!V$4:V$185) -> 1 | P12: =I12+J12 -> 1 | Q12: =B12+P12+K12+L12+M12-(D12-C12)-(H12-G12)-N12 -> -2 | R12: =SUMIF('Master list'!$E$4:$E$185,$A12,'Master list'!W$4:W$185) -> 12 | S12: =R12/3 -> 4 | T12: =Q12+S12 -> 2
A13: Ty Lockwood | B13: =SUMIF('Master list'!$E$4:$E$185,$A13,'Master list'!I$4:I$185) -> 2 | C13: =SUMIF('Master list'!$E$4:$E$185,$A13,'Master list'!J$4:J$185) -> 1 | D13: =SUMIF('Master list'!$E$4:$E$185,$A13,'Master list'!K$4:K$185) -> 1 | E13: =SUMIF('Master list'!$E$4:$E$185,$A13,'Master list'!L$4:L$185) -> 0 | F13: =SUMIF('Master list'!$E$4:$E$185,$A13,'Master list'!M$4:M$185) -> 0 | G13: =SUMIF('Master list'!$E$4:$E$185,$A13,'Master list'!N$4:N$185) -> 0 | H13: =SUMIF('Master list'!$E$4:$E$185,$A13,'Master list'!O$4:O$185) -> 0 | I13: =SUMIF('Master list'!$E$4:$E$185,$A13,'Master list'!P$4:P$185) -> 0 | ... O13: =SUMIF('Master list'!$E$4:$E$185,$A13,'Master list'!V$4:V$185) -> 0 | P13: =I13+J13 -> 0 | Q13: =B13+P13+K13+L13+M13-(D13-C13)-(H13-G13)-N13 -> 2 | R13: =SUMIF('Master list'!$E$4:$E$185,$A13,'Master list'!W$4:W$185) -> 6 | S13: =R13/3 -> 2 | T13: =Q13+S13 -> 4
A14: Dom Zaino | B14: =SUMIF('Master list'!$E$4:$E$185,$A14,'Master list'!I$4:I$185) -> 2 | C14: =SUMIF('Master list'!$E$4:$E$185,$A14,'Master list'!J$4:J$185) -> 1 | D14: =SUMIF('Master list'!$E$4:$E$185,$A14,'Master list'!K$4:K$185) -> 1 | E14: =SUMIF('Master list'!$E$4:$E$185,$A14,'Master list'!L$4:L$185) -> 0 | F14: =SUMIF('Master list'!$E$4:$E$185,$A14,'Master list'!M$4:M$185) -> 0 | G14: =SUMIF('Master list'!$E$4:$E$185,$A14,'Master list'!N$4:N$185) -> 0 | H14: =SUMIF('Master list'!$E$4:$E$185,$A14,'Master list'!O$4:O$185) -> 0 | I14: =SUMIF('Master list'!$E$4:$E$185,$A14,'Master list'!P$4:P$185) -> 0 | ... O14: =SUMIF('Master list'!$E$4:$E$185,$A14,'Master list'!V$4:V$185) -> 0 | P14: =I14+J14 -> 1 | Q14: =B14+P14+K14+L14+M14-(D14-C14)-(H14-G14)-N14 -> 3 | R14: =SUMIF('Master list'!$E$4:$E$185,$A14,'Master list'!W$4:W$185) -> 2 | S14: =R14/3 -> 0.66666667 | T14: =Q14+S14 -> 3.6666667
A15: Ariel Tsaiger | B15: =SUMIF('Master list'!$E$4:$E$185,$A15,'Master list'!I$4:I$185) -> 0 | C15: =SUMIF('Master list'!$E$4:$E$185,$A15,'Master list'!J$4:J$185) -> 0 | D15: =SUMIF('Master list'!$E$4:$E$185,$A15,'Master list'!K$4:K$185) -> 0 | E15: =SUMIF('Master list'!$E$4:$E$185,$A15,'Master list'!L$4:L$185) -> 0 | F15: =SUMIF('Master list'!$E$4:$E$185,$A15,'Master list'!M$4:M$185) -> 0 | G15: =SUMIF('Master list'!$E$4:$E$185,$A15,'Master list'!N$4:N$185) -> 0 | H15: =SUMIF('Master list'!$E$4:$E$185,$A15,'Master list'!O$4:O$185) -> 0 | I15: =SUMIF('Master list'!$E$4:$E$185,$A15,'Master list'!P$4:P$185) -> 0 | ... O15: =SUMIF('Master list'!$E$4:$E$185,$A15,'Master list'!V$4:V$185) -> 1 | P15: =I15+J15 -> 1 | Q15: =B15+P15+K15+L15+M15-(D15-C15)-(H15-G15)-N15 -> 1 | R15: =SUMIF('Master list'!$E$4:$E$185,$A15,'Master list'!W$4:W$185) -> 3 | S15: =R15/3 -> 1 | T15: =Q15+S15 -> 2
A16: Team | B16: =SUM(B4:B15) -> 37 | C16: =SUM(C4:C15) -> 13 | D16: =SUM(D4:D15) -> 32 | E16: =SUM(E4:E15) -> 2 | F16: =SUM(F4:F15) -> 10 | G16: =SUM(G4:G15) -> 9 | H16: =SUM(H4:H15) -> 12 | I16: =SUM(I4:I15) -> 6 | ... T16: =SUM(T4:T15) -> 93.333333
